Workbook

Sheet cleaned_orders_calculations
A1: order_id | B1: order_date | C1: ship_date | D1: customer_id | E1: customer_name | F1: segment | G1: region | H1: state | I1: city | J1: category | K1: sub_category | L1: product_name | M1: ship_mode | N1: quantity | O1: unit_price | P1: discount | Q1: sales | R1: cost | S1: profit | T1: payment_status | U1: order_status | V1: shipping_delay_days | W1: cleaned_discount | X1: calculated_sales | Y1: calculated_profit | Z1: profit_margin | AA1: order_month | AB1: order_year | AC1: data_quality_flag | AD1: row_text | AE1: duplicate_flag | AF1: negative_discount_flag | AG1: discount_above_range_flag | AH1: shipping_record_flag | AI1: sales_mismatch_check | AJ1: profit_mismatch_check | AK1: copy of region | AL1: copy of ship_mode
A2: ORD-2024-10001 | B2: 45494 | C2: 45500 | D2: CUST-4655 | E2: =PROPER(TRIM(raw_orders!E2)) -> Karan Malhotra | F2: =PROPER(TRIM(raw_orders!F2)) -> Consumer | G2: =PROPER(TRIM(raw_orders!G2)) -> North | H2: =PROPER(TRIM(raw_orders!H2)) -> Rajasthan | I2: =PROPER(TRIM(raw_orders!I2)) -> Jaipur | J2: =PROPER(TRIM(raw_orders!J2)) -> Office Supplies | K2: =PROPER(TRIM(raw_orders!K2)) -> Paper | L2: Pro Paper 122 | M2: =PROPER(TRIM(raw_orders!M2)) -> Second Class | N2: 8 | O2: 2976.45 | P2: 0.2 | Q2: 19049.28 | R2: 15841.89 | S2: 3207.39 | T2: =PROPER(TRIM(raw_orders!T2)) -> Paid | U2: =PROPER(TRIM(raw_orders!U2)) -> Completed | V2: =C2-B2 -> 6 | W2: =IF(AND(P2="",Q2<>"",N2<>"",S2<>""),0,IF(OR(P2<0,P2>1),P2,P2)) -> 0.2 | X2: =N2*O2*(1-P2) -> 19049.28 | Y2: =X2-R2 -> 3207.39 | Z2: =Y2/X2 -> 0.16837329 | AA2: =TEXT(B2,"MMMM") -> July | AB2: =YEAR(B2) -> 2024 | AC2: =IF(OR(AF2 = "Invalid Discount",AG2="Invalid Discount",AH2="Invalid Shipping Record",AE2="Review Required"),"Invalid",IF(OR(G2="Unknown",M2="Unknown",ISBLANK(P2)),"Warning","Clean")) -> Clean | AD2: =A2&B2&C2&D2&E2&F2&G2&H2&I2&J2&K2&L2&M2&N2&O2&P2&Q2&R2&S2&T2&U2&V2 -> ORD-2024-100014549445500CUST-4655Karan MalhotraConsumerNorthRajasthanJaipurOffice SuppliesPaperPro Paper 122Second Class82976.450.219049.2815841.893207.39PaidCompleted6 | AE2: =IF(COUNTIF($A$2:$A$933,A2)=1,"OK",IF(COUNTIF($AD$2:$AD$933,AD2)>1,"Exact Duplicate", "Review Required")) -> OK | AF2: =IF(P2<0,"Invalid Discount","") | AG2: =IF(P2>1,"Invalid Discount","") | AH2: =IF(V2<1,"Invalid Shipping Record","") | AI2: =IF(ROUND(Q2,2)=ROUND(X2,2),"Match","Mismatch") -> Match | AJ2: =IF(ROUND(S2,2)=ROUND(Y2,2),"Match","Mismatch") -> Match | AK2: =PROPER(TRIM(raw_orders!G2)) -> North | AL2: =PROPER(TRIM(raw_orders!M2)) -> Second Class
A3: ORD-2024-10002 | B3: 45535 | C3: 45540 | D3: CUST-2054 | E3: =PROPER(TRIM(raw_orders!E3)) -> Mira Das | F3: =PROPER(TRIM(raw_orders!F3)) -> Small Business | G3: =PROPER(TRIM(raw_orders!G3)) -> East | H3: =PROPER(TRIM(raw_orders!H3)) -> Odisha | I3: =PROPER(TRIM(raw_orders!I3)) -> Bhubaneswar | J3: =PROPER(TRIM(raw_orders!J3)) -> Furniture | K3: =PROPER(TRIM(raw_orders!K3)) -> Tables | L3: Pro Tables 258 | M3: =PROPER(TRIM(raw_orders!M3)) -> Same Day | N3: 3 | O3: 2437.5 | P3: 0 | Q3: 7312.5 | R3: 4904.73 | S3: 2407.77 | T3: =PROPER(TRIM(raw_orders!T3)) -> Paid | U3: =PROPER(TRIM(raw_orders!U3)) -> Completed | V3: =C3-B3 -> 5 | W3: =IF(AND(P3="",Q3<>"",N3<>"",S3<>""),0,IF(OR(P3<0,P3>1),P3,P3)) -> 0 | X3: =N3*O3*(1-P3) -> 7312.5 | Y3: =X3-R3 -> 2407.77 | Z3: =Y3/X3 -> 0.32926769 | AA3: =TEXT(B3,"MMMM") -> August | AB3: =YEAR(B3) -> 2024 | AC3: =IF(OR(AF3 = "Invalid Discount",AG3="Invalid Discount",AH3="Invalid Shipping Record",AE3="Review Required"),"Invalid",IF(OR(G3="Unknown",M3="Unknown",ISBLANK(P3)),"Warning","Clean")) -> Clean | AD3: =A3&B3&C3&D3&E3&F3&G3&H3&I3&J3&K3&L3&M3&N3&O3&P3&Q3&R3&S3&T3&U3&V3 -> ORD-2024-100024553545540CUST-2054Mira DasSmall BusinessEastOdishaBhubaneswarFurnitureTablesPro Tables 258Same Day32437.507312.54904.732407.77PaidCompleted5 | AE3: =IF(COUNTIF($A$2:$A$933,A3)=1,"OK",IF(COUNTIF($AD$2:$AD$933,AD3)>1,"Exact Duplicate", "Review Required")) -> OK | AF3: =IF(P3<0,"Invalid Discount","") | AG3: =IF(P3>1,"Invalid Discount","") | AH3: =IF(V3<1,"Invalid Shipping Record","") | AI3: =IF(ROUND(Q3,2)=ROUND(X3,2),"Match","Mismatch") -> Match | AJ3: =IF(ROUND(S3,2)=ROUND(Y3,2),"Match","Mismatch") -> Match | AK3: =PROPER(TRIM(raw_orders!G3)) -> East | AL3: =PROPER(TRIM(raw_orders!M3)) -> Same Day | AN3: Missing Region | AO3: =COUNTBLANK(AK2:AK913) -> 25
A4: ORD-2024-10003 | B4: 45451 | C4: 45458 | D4: CUST-6843 | E4: =PROPER(TRIM(raw_orders!E4)) -> Isha Nair | F4: =PROPER(TRIM(raw_orders!F4)) -> Consumer | G4: =PROPER(TRIM(raw_orders!G4)) -> East | H4: =PROPER(TRIM(raw_orders!H4)) -> Odisha | I4: =PROPER(TRIM(raw_orders!I4)) -> Bhubaneswar | J4: =PROPER(TRIM(raw_orders!J4)) -> Office Supplies | K4: =PROPER(TRIM(raw_orders!K4)) -> Art | L4: Elite Art 525 | M4: =PROPER(TRIM(raw_orders!M4)) -> First Class | N4: 4 | O4: 1065.43 | P4: 0.55 | Q4: 4261.72 | R4: 2465.69 | S4: 1796.03 | T4: =PROPER(TRIM(raw_orders!T4)) -> Paid | U4: =PROPER(TRIM(raw_orders!U4)) -> Completed | V4: =C4-B4 -> 7 | W4: =IF(AND(P4="",Q4<>"",N4<>"",S4<>""),0,IF(OR(P4<0,P4>1),P4,P4)) -> 0.55 | X4: =N4*O4*(1-P4) -> 1917.774 | Y4: =X4-R4 -> -547.916 | Z4: =Y4/X4 -> -0.28570415 | AA4: =TEXT(B4,"MMMM") -> June | AB4: =YEAR(B4) -> 2024 | AC4: =IF(OR(AF4 = "Invalid Discount",AG4="Invalid Discount",AH4="Invalid Shipping Record",AE4="Review Required"),"Invalid",IF(OR(G4="Unknown",M4="Unknown",ISBLANK(P4)),"Warning","Clean")) -> Clean | AD4: =A4&B4&C4&D4&E4&F4&G4&H4&I4&J4&K4&L4&M4&N4&O4&P4&Q4&R4&S4&T4&U4&V4 -> ORD-2024-100034545145458CUST-6843Isha NairConsumerEastOdishaBhubaneswarOffice SuppliesArtElite Art 525First Class41065.430.554261.722465.691796.03PaidCompleted7 | AE4: =IF(COUNTIF($A$2:$A$933,A4)=1,"OK",IF(COUNTIF($AD$2:$AD$933,AD4)>1,"Exact Duplicate", "Review Required")) -> OK | AF4: =IF(P4<0,"Invalid Discount","") | AG4: =IF(P4>1,"Invalid Discount","") | AH4: =IF(V4<1,"Invalid Shipping Record","") | AI4: =IF(ROUND(Q4,2)=ROUND(X4,2),"Match","Mismatch") -> Mismatch | AJ4: =IF(ROUND(S4,2)=ROUND(Y4,2),"Match","Mismatch") -> Mismatch | AK4: =PROPER(TRIM(raw_orders!G4)) -> East | AL4: =PROPER(TRIM(raw_orders!M4)) -> First Class | AN4: Missing Ship Mode | AO4: =COUNTBLANK(AL2:AL913) -> 21
A5: ORD-2024-10004 | B5: 45624 | C5: 45625 | D5: CUST-3722 | E5: =PROPER(TRIM(raw_orders!E5)) -> Arjun Bose | F5: =PROPER(TRIM(raw_orders!F5)) -> Small Business | G5: =PROPER(TRIM(raw_orders!G5)) -> South | H5: =PROPER(TRIM(raw_orders!H5)) -> Telangana | I5: =PROPER(TRIM(raw_orders!I5)) -> Hyderabad | J5: =PROPER(TRIM(raw_orders!J5)) -> Furniture | K5: =PROPER(TRIM(raw_orders!K5)) -> Furnishings | L5: Smart Furnishings 294 | M5: =PROPER(TRIM(raw_orders!M5)) -> Standard Class | N5: 6 | O5: 1848.43 | P5: 0.25 | Q5: 8317.93 | R5: 6796.77 | S5: 1521.16 | T5: =PROPER(TRIM(raw_orders!T5)) -> Paid | U5: =PROPER(TRIM(raw_orders!U5)) -> Completed | V5: =C5-B5 -> 1 | W5: =IF(AND(P5="",Q5<>"",N5<>"",S5<>""),0,IF(OR(P5<0,P5>1),P5,P5)) -> 0.25 | X5: =N5*O5*(1-P5) -> 8317.935 | Y5: =X5-R5 -> 1521.165 | Z5: =Y5/X5 -> 0.18287772 | AA5: =TEXT(B5,"MMMM") -> November | AB5: =YEAR(B5) -> 2024 | AC5: =IF(OR(AF5 = "Invalid Discount",AG5="Invalid Discount",AH5="Invalid Shipping Record",AE5="Review Required"),"Invalid",IF(OR(G5="Unknown",M5="Unknown",ISBLANK(P5)),"Warning","Clean")) -> Clean | AD5: =A5&B5&C5&D5&E5&F5&G5&H5&I5&J5&K5&L5&M5&N5&O5&P5&Q5&R5&S5&T5&U5&V5 -> ORD-2024-100044562445625CUST-3722Arjun BoseSmall BusinessSouthTelanganaHyderabadFurnitureFurnishingsSmart Furnishings 294Standard Class61848.430.258317.936796.771521.16PaidCompleted1 | AE5: =IF(COUNTIF($A$2:$A$933,A5)=1,"OK",IF(COUNTIF($AD$2:$AD$933,AD5)>1,"Exact Duplicate", "Review Required")) -> OK | AF5: =IF(P5<0,"Invalid Discount","") | AG5: =IF(P5>1,"Invalid Discount","") | AH5: =IF(V5<1,"Invalid Shipping Record","") | AI5: =IF(ROUND(Q5,2)=ROUND(X5,2),"Match","Mismatch") -> Mismatch | AJ5: =IF(ROUND(S5,2)=ROUND(Y5,2),"Match","Mismatch") -> Mismatch | AK5: =PROPER(TRIM(raw_orders!G5)) -> South | AL5: =PROPER(TRIM(raw_orders!M5)) -> Standard Class | AN5: Missing Discount | AO5: =COUNTBLANK(P2:P913) -> 18
A6: ORD-2025-10005 | B6: 45898 | C6: 45901 | D6: CUST-8130 | E6: =PROPER(TRIM(raw_orders!E6)) -> Ananya Rao | F6: =PROPER(TRIM(raw_orders!F6)) -> Small Business | G6: =PROPER(TRIM(raw_orders!G6)) -> West | H6: =PROPER(TRIM(raw_orders!H6)) -> Maharashtra | I6: =PROPER(TRIM(raw_orders!I6)) -> Mumbai | J6: =PROPER(TRIM(raw_orders!J6)) -> Furniture | K6: =PROPER(TRIM(raw_orders!K6)) -> Chairs | L6: Elite Chairs 543 | M6: =PROPER(TRIM(raw_orders!M6)) -> First Class | N6: 7 | O6: 2973.76 | P6: 0 | Q6: 20816.32 | R6: 17705.37 | S6: 3110.95 | T6: =PROPER(TRIM(raw_orders!T6)) -> Paid | U6: =PROPER(TRIM(raw_orders!U6)) -> Cancelled | V6: =C6-B6 -> 3 | W6: =IF(AND(P6="",Q6<>"",N6<>"",S6<>""),0,IF(OR(P6<0,P6>1),P6,P6)) -> 0 | X6: =N6*O6*(1-P6) -> 20816.32 | Y6: =X6-R6 -> 3110.95 | Z6: =Y6/X6 -> 0.14944764 | AA6: =TEXT(B6,"MMMM") -> August | AB6: =YEAR(B6) -> 2025 | AC6: =IF(OR(AF6 = "Invalid Discount",AG6="Invalid Discount",AH6="Invalid Shipping Record",AE6="Review Required"),"Invalid",IF(OR(G6="Unknown",M6="Unknown",ISBLANK(P6)),"Warning","Clean")) -> Clean | AD6: =A6&B6&C6&D6&E6&F6&G6&H6&I6&J6&K6&L6&M6&N6&O6&P6&Q6&R6&S6&T6&U6&V6 -> ORD-2025-100054589845901CUST-8130Ananya RaoSmall BusinessWestMaharashtraMumbaiFurnitureChairsElite Chairs 543First Class72973.76020816.3217705.373110.95PaidCancelled3 | AE6: =IF(COUNTIF($A$2:$A$933,A6)=1,"OK",IF(COUNTIF($AD$2:$AD$933,AD6)>1,"Exact Duplicate", "Review Required")) -> OK | AF6: =IF(P6<0,"Invalid Discount","") | AG6: =IF(P6>1,"Invalid Discount","") | AH6: =IF(V6<1,"Invalid Shipping Record","") | AI6: =IF(ROUND(Q6,2)=ROUND(X6,2),"Match","Mismatch") -> Match | AJ6: =IF(ROUND(S6,2)=ROUND(Y6,2),"Match","Mismatch") -> Match | AK6: =PROPER(TRIM(raw_orders!G6)) -> West | AL6: =PROPER(TRIM(raw_orders!M6)) -> First Class | AN6: Negative discount | AO6: =COUNTIF(P2:P913,"<0") -> 15
A7: ORD-2024-10006 | B7: 45436 | C7: 45440 | D7: CUST-6056 | E7: =PROPER(TRIM(raw_orders!E7)) -> Vikram Iyer | F7: =PROPER(TRIM(raw_orders!F7)) -> Small Business | G7: =PROPER(TRIM(raw_orders!G7)) -> West | H7: =PROPER(TRIM(raw_orders!H7)) -> Madhya Pradesh | I7: =PROPER(TRIM(raw_orders!I7)) -> Indore | J7: =PROPER(TRIM(raw_orders!J7)) -> Technology | K7: =PROPER(TRIM(raw_orders!K7)) -> Accessories | L7: Pro Accessories 821 | M7: =PROPER(TRIM(raw_orders!M7)) -> Same Day | N7: 3 | O7: 1053.11 | P7: 0.2 | Q7: 2527.46 | R7: 1533.58 | S7: 993.88 | T7: =PROPER(TRIM(raw_orders!T7)) -> Paid | U7: =PROPER(TRIM(raw_orders!U7)) -> Completed | V7: =C7-B7 -> 4 | W7: =IF(AND(P7="",Q7<>"",N7<>"",S7<>""),0,IF(OR(P7<0,P7>1),P7,P7)) -> 0.2 | X7: =N7*O7*(1-P7) -> 2527.464 | Y7: =X7-R7 -> 993.884 | Z7: =Y7/X7 -> 0.39323369 | AA7: =TEXT(B7,"MMMM") -> May | AB7: =YEAR(B7) -> 2024 | AC7: =IF(OR(AF7 = "Invalid Discount",AG7="Invalid Discount",AH7="Invalid Shipping Record",AE7="Review Required"),"Invalid",IF(OR(G7="Unknown",M7="Unknown",ISBLANK(P7)),"Warning","Clean")) -> Clean | AD7: =A7&B7&C7&D7&E7&F7&G7&H7&I7&J7&K7&L7&M7&N7&O7&P7&Q7&R7&S7&T7&U7&V7 -> ORD-2024-100064543645440CUST-6056Vikram IyerSmall BusinessWestMadhya PradeshIndoreTechnologyAccessoriesPro Accessories 821Same Day31053.110.22527.461533.58993.88PaidCompleted4 | AE7: =IF(COUNTIF($A$2:$A$933,A7)=1,"OK",IF(COUNTIF($AD$2:$AD$933,AD7)>1,"Exact Duplicate", "Review Required")) -> OK | AF7: =IF(P7<0,"Invalid Discount","") | AG7: =IF(P7>1,"Invalid Discount","") | AH7: =IF(V7<1,"Invalid Shipping Record","") | AI7: =IF(ROUND(Q7,2)=ROUND(X7,2),"Match","Mismatch") -> Match | AJ7: =IF(ROUND(S7,2)=ROUND(Y7,2),"Match","Mismatch") -> Match | AK7: =PROPER(TRIM(raw_orders!G7)) -> West | AL7: =PROPER(TRIM(raw_orders!M7)) -> Same Day | AN7: Discount Above Range | AO7: =COUNTIF(AG2:AG913,"Invalid Discount") -> 0
A8: ORD-2025-10007 | B8: 45757 | C8: 45763 | D8: CUST-3656 | E8: =PROPER(TRIM(raw_orders!E8)) -> Neha Gupta | F8: =PROPER(TRIM(raw_orders!F8)) -> Consumer | G8: =PROPER(TRIM(raw_orders!G8)) -> East | H8: =PROPER(TRIM(raw_orders!H8)) -> Odisha | I8: =PROPER(TRIM(raw_orders!I8)) -> Bhubaneswar | J8: =PROPER(TRIM(raw_orders!J8)) -> Technology | K8: =PROPER(TRIM(raw_orders!K8)) -> Copiers | L8: Eco Copiers 790 | M8: =PROPER(TRIM(raw_orders!M8)) -> Standard Class | N8: 4 | O8: 1719.87 | P8: 0.15 | Q8: 5847.56 | R8: 4727.25 | S8: 1120.31 | T8: =PROPER(TRIM(raw_orders!T8)) -> Paid | U8: =PROPER(TRIM(raw_orders!U8)) -> Completed | V8: =C8-B8 -> 6 | W8: =IF(AND(P8="",Q8<>"",N8<>"",S8<>""),0,IF(OR(P8<0,P8>1),P8,P8)) -> 0.15 | X8: =N8*O8*(1-P8) -> 5847.558 | Y8: =X8-R8 -> 1120.308 | Z8: =Y8/X8 -> 0.19158562 | AA8: =TEXT(B8,"MMMM") -> April | AB8: =YEAR(B8) -> 2025 | AC8: =IF(OR(AF8 = "Invalid Discount",AG8="Invalid Discount",AH8="Invalid Shipping Record",AE8="Review Required"),"Invalid",IF(OR(G8="Unknown",M8="Unknown",ISBLANK(P8)),"Warning","Clean")) -> Clean | AD8: =A8&B8&C8&D8&E8&F8&G8&H8&I8&J8&K8&L8&M8&N8&O8&P8&Q8&R8&S8&T8&U8&V8 -> ORD-2025-100074575745763CUST-3656Neha GuptaConsumerEastOdishaBhubaneswarTechnologyCopiersEco Copiers 790Standard Class41719.870.155847.564727.251120.31PaidCompleted6 | AE8: =IF(COUNTIF($A$2:$A$933,A8)=1,"OK",IF(COUNTIF($AD$2:$AD$933,AD8)>1,"Exact Duplicate", "Review Required")) -> OK | AF8: =IF(P8<0,"Invalid Discount","") | AG8: =IF(P8>1,"Invalid Discount","") | AH8: =IF(V8<1,"Invalid Shipping Record","") | AI8: =IF(ROUND(Q8,2)=ROUND(X8,2),"Match","Mismatch") -> Match | AJ8: =IF(ROUND(S8,2)=ROUND(Y8,2),"Match","Mismatch") -> Match | AK8: =PROPER(TRIM(raw_orders!G8)) -> East | AL8: =PROPER(TRIM(raw_orders!M8)) -> Standard Class
A9: ORD-2025-10008 | B9: 45711 | C9: 45714 | D9: CUST-4683 | E9: =PROPER(TRIM(raw_orders!E9)) -> Isha Nair | F9: =PROPER(TRIM(raw_orders!F9)) -> Small Business | G9: =PROPER(TRIM(raw_orders!G9)) -> South | H9: =PROPER(TRIM(raw_orders!H9)) -> Andhra Pradesh | I9: =PROPER(TRIM(raw_orders!I9)) -> Vijayawada | J9: =PROPER(TRIM(raw_orders!J9)) -> Office Supplies | K9: =PROPER(TRIM(raw_orders!K9)) -> Art | L9: Eco Art 848 | M9: =PROPER(TRIM(raw_orders!M9)) -> First Class | N9: 1 | O9: 2980.71 | P9: 0 | Q9: 2980.71 | R9: 2357.22 | S9: 623.49 | T9: =PROPER(TRIM(raw_orders!T9)) -> Paid | U9: =PROPER(TRIM(raw_orders!U9)) -> Completed | V9: =C9-B9 -> 3 | W9: =IF(AND(P9="",Q9<>"",N9<>"",S9<>""),0,IF(OR(P9<0,P9>1),P9,P9)) -> 0 | X9: =N9*O9*(1-P9) -> 2980.71 | Y9: =X9-R9 -> 623.49 | Z9: =Y9/X9 -> 0.209175 | AA9: =TEXT(B9,"MMMM") -> February | AB9: =YEAR(B9) -> 2025 | AC9: =IF(OR(AF9 = "Invalid Discount",AG9="Invalid Discount",AH9="Invalid Shipping Record",AE9="Review Required"),"Invalid",IF(OR(G9="Unknown",M9="Unknown",ISBLANK(P9)),"Warning","Clean")) -> Clean | AD9: =A9&B9&C9&D9&E9&F9&G9&H9&I9&J9&K9&L9&M9&N9&O9&P9&Q9&R9&S9&T9&U9&V9 -> ORD-2025-100084571145714CUST-4683Isha NairSmall BusinessSouthAndhra PradeshVijayawadaOffice SuppliesArtEco Art 848First Class12980.7102980.712357.22623.49PaidCompleted3 | AE9: =IF(COUNTIF($A$2:$A$933,A9)=1,"OK",IF(COUNTIF($AD$2:$AD$933,AD9)>1,"Exact Duplicate", "Review Required")) -> OK | AF9: =IF(P9<0,"Invalid Discount","") | AG9: =IF(P9>1,"Invalid Discount","") | AH9: =IF(V9<1,"Invalid Shipping Record","") | AI9: =IF(ROUND(Q9,2)=ROUND(X9,2),"Match","Mismatch") -> Match | AJ9: =IF(ROUND(S9,2)=ROUND(Y9,2),"Match","Mismatch") -> Match | AK9: =PROPER(TRIM(raw_orders!G9)) -> South | AL9: =PROPER(TRIM(raw_orders!M9)) -> First Class | AN9: Cancelled Orders | AO9: =COUNTIF(U:U,"Cancelled") -> 145
A10: ORD-2024-10009 | B10: 45601 | C10: 45606 | D10: CUST-2598 | E10: =PROPER(TRIM(raw_orders!E10)) -> Aditi Sen | F10: =PROPER(TRIM(raw_orders!F10)) -> Corporate | G10: =PROPER(TRIM(raw_orders!G10)) -> South | H10: =PROPER(TRIM(raw_orders!H10)) -> Telangana | I10: =PROPER(TRIM(raw_orders!I10)) -> Hyderabad | J10: =PROPER(TRIM(raw_orders!J10)) -> Office Supplies | K10: =PROPER(TRIM(raw_orders!K10)) -> Labels | L10: Classic Labels 815 | M10: =PROPER(TRIM(raw_orders!M10)) -> First Class | N10: 8 | O10: 3134.2 | P10: 0 | Q10: 25073.6 | R10: 17347.23 | S10: 7726.37 | T10: =PROPER(TRIM(raw_orders!T10)) -> Paid | U10: =PROPER(TRIM(raw_orders!U10)) -> Completed | V10: =C10-B10 -> 5 | W10: =IF(AND(P10="",Q10<>"",N10<>"",S10<>""),0,IF(OR(P10<0,P10>1),P10,P10)) -> 0 | X10: =N10*O10*(1-P10) -> 25073.6 | Y10: =X10-R10 -> 7726.37 | Z10: =Y10/X10 -> 0.30814761 | AA10: =TEXT(B10,"MMMM") -> November | AB10: =YEAR(B10) -> 2024 | AC10: =IF(OR(AF10 = "Invalid Discount",AG10="Invalid Discount",AH10="Invalid Shipping Record",AE10="Review Required"),"Invalid",IF(OR(G10="Unknown",M10="Unknown",ISBLANK(P10)),"Warning","Clean")) -> Clean | AD10: =A10&B10&C10&D10&E10&F10&G10&H10&I10&J10&K10&L10&M10&N10&O10&P10&Q10&R10&S10&T10&U10&V10 -> ORD-2024-100094560145606CUST-2598Aditi SenCorporateSouthTelanganaHyderabadOffice SuppliesLabelsClassic Labels 815First Class83134.2025073.617347.237726.37PaidCompleted5 | AE10: =IF(COUNTIF($A$2:$A$933,A10)=1,"OK",IF(COUNTIF($AD$2:$AD$933,AD10)>1,"Exact Duplicate", "Review Required")) -> OK | AF10: =IF(P10<0,"Invalid Discount","") | AG10: =IF(P10>1,"Invalid Discount","") | AH10: =IF(V10<1,"Invalid Shipping Record","") | AI10: =IF(ROUND(Q10,2)=ROUND(X10,2),"Match","Mismatch") -> Match | AJ10: =IF(ROUND(S10,2)=ROUND(Y10,2),"Match","Mismatch") -> Match | AK10: =PROPER(TRIM(raw_orders!G10)) -> South | AL10: =PROPER(TRIM(raw_orders!M10)) -> First Class | AN10: Completed Orders | AO10: =COUNTIF(U:U,"Completed") -> 604
A11: ORD-2025-10010 | B11: 45847 | C11: 45912 | D11: CUST-2483 | E11: =PROPER(TRIM(raw_orders!E11)) -> Mira Das | F11: =PROPER(TRIM(raw_orders!F11)) -> Home Office | G11: =PROPER(TRIM(raw_orders!G11)) -> South | H11: =PROPER(TRIM(raw_orders!H11)) -> Telangana | I11: =PROPER(TRIM(raw_orders!I11)) -> Hyderabad | J11: =PROPER(TRIM(raw_orders!J11)) -> Office Supplies | K11: =PROPER(TRIM(raw_orders!K11)) -> Paper | L11: Pro Paper 622 | M11: =PROPER(TRIM(raw_orders!M11)) -> Second Class | N11: 9 | O11: 852.04 | P11: 0.2 | Q11: 6134.69 | R11: 3800.19 | S11: 2334.5 | T11: =PROPER(TRIM(raw_orders!T11)) -> Paid | U11: =PROPER(TRIM(raw_orders!U11)) -> Completed | V11: =C11-B11 -> 65 | W11: =IF(AND(P11="",Q11<>"",N11<>"",S11<>""),0,IF(OR(P11<0,P11>1),P11,P11)) -> 0.2 | X11: =N11*O11*(1-P11) -> 6134.688 | Y11: =X11-R11 -> 2334.498 | Z11: =Y11/X11 -> 0.38054062 | AA11: =TEXT(B11,"MMMM") -> July | AB11: =YEAR(B11) -> 2025 | AC11: =IF(OR(AF11 = "Invalid Discount",AG11="Invalid Discount",AH11="Invalid Shipping Record",AE11="Review Required"),"Invalid",IF(OR(G11="Unknown",M11="Unknown",ISBLANK(P11)),"Warning","Clean")) -> Clean | AD11: =A11&B11&C11&D11&E11&F11&G11&H11&I11&J11&K11&L11&M11&N11&O11&P11&Q11&R11&S11&T11&U11&V11 -> ORD-2025-100104584745912CUST-2483Mira DasHome OfficeSouthTelanganaHyderabadOffice SuppliesPaperPro Paper 622Second Class9852.040.26134.693800.192334.5PaidCompleted65 | AE11: =IF(COUNTIF($A$2:$A$933,A11)=1,"OK",IF(COUNTIF($AD$2:$AD$933,AD11)>1,"Exact Duplicate", "Review Required")) -> OK | AF11: =IF(P11<0,"Invalid Discount","") | AG11: =IF(P11>1,"Invalid Discount","") | AH11: =IF(V11<1,"Invalid Shipping Record","") | AI11: =IF(ROUND(Q11,2)=ROUND(X11,2),"Match","Mismatch") -> Match | AJ11: =IF(ROUND(S11,2)=ROUND(Y11,2),"Match","Mismatch") -> Match | AK11: =PROPER(TRIM(raw_orders!G11)) -> South | AL11: =PROPER(TRIM(raw_orders!M11)) -> Second Class | AN11: Refunded Orders | AO11: =COUNTIF(U:U,"Returned") -> 163
A12: ORD-2025-10011 | B12: 45797 | C12: 45797 | D12: CUST-8092 | E12: =PROPER(TRIM(raw_orders!E12)) -> Ananya Rao | F12: =PROPER(TRIM(raw_orders!F12)) -> Corporate | G12: =PROPER(TRIM(raw_orders!G12)) -> East | H12: =PROPER(TRIM(raw_orders!H12)) -> West Bengal | I12: =PROPER(TRIM(raw_orders!I12)) -> Kolkata | J12: =PROPER(TRIM(raw_orders!J12)) -> Office Supplies | K12: =PROPER(TRIM(raw_orders!K12)) -> Labels | L12: Prime Labels 644 | M12: =PROPER(TRIM(raw_orders!M12)) -> Second Class | N12: 3 | O12: 3534.83 | P12: 0.05 | Q12: 10074.27 | R12: 6048.27 | S12: 4026 | T12: =PROPER(TRIM(raw_orders!T12)) -> Refunded | U12: =PROPER(TRIM(raw_orders!U12)) -> Returned | V12: =C12-B12 -> 0 | W12: =IF(AND(P12="",Q12<>"",N12<>"",S12<>""),0,IF(OR(P12<0,P12>1),P12,P12)) -> 0.05 | X12: =N12*O12*(1-P12) -> 10074.265 | Y12: =X12-R12 -> 4025.9955 | Z12: =Y12/X12 -> 0.39963167 | AA12: =TEXT(B12,"MMMM") -> May | AB12: =YEAR(B12) -> 2025 | AC12: =IF(OR(AF12 = "Invalid Discount",AG12="Invalid Discount",AH12="Invalid Shipping Record",AE12="Review Required"),"Invalid",IF(OR(G12="Unknown",M12="Unknown",ISBLANK(P12)),"Warning","Clean")) -> Clean | AD12: =A12&B12&C12&D12&E12&F12&G12&H12&I12&J12&K12&L12&M12&N12&O12&P12&Q12&R12&S12&T12&U12&V12 -> ORD-2025-100114579745797CUST-8092Ananya RaoCorporateEastWest BengalKolkataOffice SuppliesLabelsPrime Labels 644Second Class33534.830.0510074.276048.274026RefundedReturned0 | AE12: =IF(COUNTIF($A$2:$A$933,A12)=1,"OK",IF(COUNTIF($AD$2:$AD$933,AD12)>1,"Exact Duplicate", "Review Required")) -> OK | AF12: =IF(P12<0,"Invalid Discount","") | AG12: =IF(P12>1,"Invalid Discount","") | AH12: =IF(V12<0,"Invalid Shipping Record","") | AI12: =IF(ROUND(Q12,2)=ROUND(X12,2),"Match","Mismatch") -> Match | AJ12: =IF(ROUND(S12,2)=ROUND(Y12,2),"Match","Mismatch") -> Match | AK12: =PROPER(TRIM(raw_orders!G12)) -> East | AL12: =PROPER(TRIM(raw_orders!M12)) -> Second Class | AN12: Failed Payments | AO12: =COUNTIF(T:T,"Failed") -> 69
A13: ORD-2024-10012 | B13: 45495 | C13: 45496 | D13: CUST-6528 | E13: =PROPER(TRIM(raw_orders!E13)) -> Vikram Iyer | F13: =PROPER(TRIM(raw_orders!F13)) -> Small Business | G13: =PROPER(TRIM(raw_orders!G13)) -> East | H13: =PROPER(TRIM(raw_orders!H13)) -> Odisha | I13: =PROPER(TRIM(raw_orders!I13)) -> Bhubaneswar | J13: =PROPER(TRIM(raw_orders!J13)) -> Technology | K13: =PROPER(TRIM(raw_orders!K13)) -> Accessories | L13: Smart Accessories 603 | M13: =PROPER(TRIM(raw_orders!M13)) -> Same Day | N13: 6 | O13: 2005.95 | P13: 0.2 | Q13: 9628.56 | R13: 8038.59 | S13: 1589.97 | T13: =PROPER(TRIM(raw_orders!T13)) -> Paid | U13: =PROPER(TRIM(raw_orders!U13)) -> Completed | V13: =C13-B13 -> 1 | W13: =IF(AND(P13="",Q13<>"",N13<>"",S13<>""),0,IF(OR(P13<0,P13>1),P13,P13)) -> 0.2 | X13: =N13*O13*(1-P13) -> 9628.56 | Y13: =X13-R13 -> 1589.97 | Z13: =Y13/X13 -> 0.16513061 | AA13: =TEXT(B13,"MMMM") -> July | AB13: =YEAR(B13) -> 2024 | AC13: =IF(OR(AF13 = "Invalid Discount",AG13="Invalid Discount",AH13="Invalid Shipping Record",AE13="Review Required"),"Invalid",IF(OR(G13="Unknown",M13="Unknown",ISBLANK(P13)),"Warning","Clean")) -> Clean | AD13: =A13&B13&C13&D13&E13&F13&G13&H13&I13&J13&K13&L13&M13&N13&O13&P13&Q13&R13&S13&T13&U13&V13 -> ORD-2024-100124549545496CUST-6528Vikram IyerSmall BusinessEastOdishaBhubaneswarTechnologyAccessoriesSmart Accessories 603Same Day62005.950.29628.568038.591589.97PaidCompleted1 | AE13: =IF(COUNTIF($A$2:$A$933,A13)=1,"OK",IF(COUNTIF($AD$2:$AD$933,AD13)>1,"Exact Duplicate", "Review Required")) -> OK | AF13: =IF(P13<0,"Invalid Discount","") | AG13: =IF(P13>1,"Invalid Discount","") | AH13: =IF(V13<1,"Invalid Shipping Record","") | AI13: =IF(ROUND(Q13,2)=ROUND(X13,2),"Match","Mismatch") -> Match | AJ13: =IF(ROUND(S13,2)=ROUND(Y13,2),"Match","Mismatch") -> Match | AK13: =PROPER(TRIM(raw_orders!G13)) -> East | AL13: =PROPER(TRIM(raw_orders!M13)) -> Same Day | AN13: Refunded Orders | AO13: =COUNTIF(T:T,"Refunded") -> 71
A14: ORD-2024-10013 | B14: 45646 | C14: 45647 | D14: CUST-2648 | E14: =PROPER(TRIM(raw_orders!E14)) -> Ananya Rao | F14: =PROPER(TRIM(raw_orders!F14)) -> Corporate | G14: =PROPER(TRIM(raw_orders!G14)) -> West | H14: =PROPER(TRIM(raw_orders!H14)) -> Rajasthan | I14: =PROPER(TRIM(raw_orders!I14)) -> Udaipur | J14: =PROPER(TRIM(raw_orders!J14)) -> Office Supplies | K14: =PROPER(TRIM(raw_orders!K14)) -> Paper | L14: Pro Paper 481 | M14: =PROPER(TRIM(raw_orders!M14)) -> First Class | N14: 1 | O14: 702.14 | P14: 0.15 | Q14: 596.82 | R14: 380.25 | S14: 216.57 | T14: =PROPER(TRIM(raw_orders!T14)) -> Pending | U14: =PROPER(TRIM(raw_orders!U14)) -> Returned | V14: =C14-B14 -> 1 | W14: =IF(AND(P14="",Q14<>"",N14<>"",S14<>""),0,IF(OR(P14<0,P14>1),P14,P14)) -> 0.15 | X14: =N14*O14*(1-P14) -> 596.819 | Y14: =X14-R14 -> 216.569 | Z14: =Y14/X14 -> 0.36287216 | AA14: =TEXT(B14,"MMMM") -> December | AB14: =YEAR(B14) -> 2024 | AC14: =IF(OR(AF14 = "Invalid Discount",AG14="Invalid Discount",AH14="Invalid Shipping Record",AE14="Review Required"),"Invalid",IF(OR(G14="Unknown",M14="Unknown",ISBLANK(P14)),"Warning","Clean")) -> Clean | AD14: =A14&B14&C14&D14&E14&F14&G14&H14&I14&J14&K14&L14&M14&N14&O14&P14&Q14&R14&S14&T14&U14&V14 -> ORD-2024-100134564645647CUST-2648Ananya RaoCorporateWestRajasthanUdaipurOffice SuppliesPaperPro Paper 481First Class1702.140.15596.82380.25216.57PendingReturned1 | AE14: =IF(COUNTIF($A$2:$A$933,A14)=1,"OK",IF(COUNTIF($AD$2:$AD$933,AD14)>1,"Exact Duplicate", "Review Required")) -> OK | AF14: =IF(P14<0,"Invalid Discount","") | AG14: =IF(P14>1,"Invalid Discount","") | AH14: =IF(V14<1,"Invalid Shipping Record","") | AI14: =IF(ROUND(Q14,2)=ROUND(X14,2),"Match","Mismatch") -> Match | AJ14: =IF(ROUND(S14,2)=ROUND(Y14,2),"Match","Mismatch") -> Match | AK14: =PROPER(TRIM(raw_orders!G14)) -> West | AL14: =PROPER(TRIM(raw_orders!M14)) -> First Class
A15: ORD-2025-10014 | B15: 45942 | C15: 45946 | D15: CUST-7482 | E15: =PROPER(TRIM(raw_orders!E15)) -> Priya Menon | F15: =PROPER(TRIM(raw_orders!F15)) -> Small Business | G15: =PROPER(TRIM(raw_orders!G15)) -> West | H15: =PROPER(TRIM(raw_orders!H15)) -> Maharashtra | I15: =PROPER(TRIM(raw_orders!I15)) -> Mumbai | J15: =PROPER(TRIM(raw_orders!J15)) -> Office Supplies | K15: =PROPER(TRIM(raw_orders!K15)) -> Art | L15: Smart Art 795 | M15: =PROPER(TRIM(raw_orders!M15)) -> Second Class | N15: 7 | O15: 3964.72 | P15: 0.05 | Q15: 26365.39 | R15: 22306.24 | S15: 4059.15 | T15: =PROPER(TRIM(raw_orders!T15)) -> Paid | U15: =PROPER(TRIM(raw_orders!U15)) -> Completed | V15: =C15-B15 -> 4 | W15: =IF(AND(P15="",Q15<>"",N15<>"",S15<>""),0,IF(OR(P15<0,P15>1),P15,P15)) -> 0.05 | X15: =N15*O15*(1-P15) -> 26365.388 | Y15: =X15-R15 -> 4059.148 | Z15: =Y15/X15 -> 0.15395745 | AA15: =TEXT(B15,"MMMM") -> October | AB15: =YEAR(B15) -> 2025 | AC15: =IF(OR(AF15 = "Invalid Discount",AG15="Invalid Discount",AH15="Invalid Shipping Record",AE15="Review Required"),"Invalid",IF(OR(G15="Unknown",M15="Unknown",ISBLANK(P15)),"Warning","Clean")) -> Clean | AD15: =A15&B15&C15&D15&E15&F15&G15&H15&I15&J15&K15&L15&M15&N15&O15&P15&Q15&R15&S15&T15&U15&V15 -> ORD-2025-100144594245946CUST-7482Priya MenonSmall BusinessWestMaharashtraMumbaiOffice SuppliesArtSmart Art 795Second Class73964.720.0526365.3922306.244059.15PaidCompleted4 | AE15: =IF(COUNTIF($A$2:$A$933,A15)=1,"OK",IF(COUNTIF($AD$2:$AD$933,AD15)>1,"Exact Duplicate", "Review Required")) -> OK | AF15: =IF(P15<0,"Invalid Discount","") | AG15: =IF(P15>1,"Invalid Discount","") | AH15: =IF(V15<1,"Invalid Shipping Record","") | AI15: =IF(ROUND(Q15,2)=ROUND(X15,2),"Match","Mismatch") -> Match | AJ15: =IF(ROUND(S15,2)=ROUND(Y15,2),"Match","Mismatch") -> Match | AK15: =PROPER(TRIM(raw_orders!G15)) -> West | AL15: =PROPER(TRIM(raw_orders!M15)) -> Second Class
A16: ORD-2024-10015 | B16: 45653 | C16: 45654 | D16: CUST-4912 | E16: =PROPER(TRIM(raw_orders!E16)) -> Rahul Verma | F16: =PROPER(TRIM(raw_orders!F16)) -> Consumer | G16: =PROPER(TRIM(raw_orders!G16)) -> West | H16: =PROPER(TRIM(raw_orders!H16)) -> Rajasthan | I16: =PROPER(TRIM(raw_orders!I16)) -> Udaipur | J16: =PROPER(TRIM(raw_orders!J16)) -> Technology | K16: =PROPER(TRIM(raw_orders!K16)) -> Copiers | L16: Max Copiers 983 | M16: =PROPER(TRIM(raw_orders!M16)) -> Standard Class | N16: 2 | O16: 2737.83 | P16: 0.25 | Q16: 4106.74 | R16: 2666.3 | S16: 1440.44 | T16: =PROPER(TRIM(raw_orders!T16)) -> Paid | U16: =PROPER(TRIM(raw_orders!U16)) -> Completed | V16: =C16-B16 -> 1 | W16: =IF(AND(P16="",Q16<>"",N16<>"",S16<>""),0,IF(OR(P16<0,P16>1),P16,P16)) -> 0.25 | X16: =N16*O16*(1-P16) -> 4106.745 | Y16: =X16-R16 -> 1440.445 | Z16: =Y16/X16 -> 0.35075102 | AA16: =TEXT(B16,"MMMM") -> December | AB16: =YEAR(B16) -> 2024 | AC16: =IF(OR(AF16 = "Invalid Discount",AG16="Invalid Discount",AH16="Invalid Shipping Record",AE16="Review Required"),"Invalid",IF(OR(G16="Unknown",M16="Unknown",ISBLANK(P16)),"Warning","Clean")) -> Clean | AD16: =A16&B16&C16&D16&E16&F16&G16&H16&I16&J16&K16&L16&M16&N16&O16&P16&Q16&R16&S16&T16&U16&V16 -> ORD-2024-100154565345654CUST-4912Rahul VermaConsumerWestRajasthanUdaipurTechnologyCopiersMax Copiers 983Standard Class22737.830.254106.742666.31440.44PaidCompleted1 | AE16: =IF(COUNTIF($A$2:$A$933,A16)=1,"OK",IF(COUNTIF($AD$2:$AD$933,AD16)>1,"Exact Duplicate", "Review Required")) -> OK | AF16: =IF(P16<0,"Invalid Discount","") | AG16: =IF(P16>1,"Invalid Discount","") | AH16: =IF(V16<1,"Invalid Shipping Record","") | AI16: =IF(ROUND(Q16,2)=ROUND(X16,2),"Match","Mismatch") -> Mismatch | AJ16: =IF(ROUND(S16,2)=ROUND(Y16,2),"Match","Mismatch") -> Mismatch | AK16: =PROPER(TRIM(raw_orders!G16)) -> West | AL16: =PROPER(TRIM(raw_orders!M16)) -> Standard Class | AN16: Ship date before order date | AO16: =COUNTIF(V:V,"<0") -> 93
A17: ORD-2024-10016 | B17: 45482 | C17: 45482 | D17: CUST-7656 | E17: =PROPER(TRIM(raw_orders!E17)) -> Karan Malhotra | F17: =PROPER(TRIM(raw_orders!F17)) -> Small Business | G17: =PROPER(TRIM(raw_orders!G17)) -> North | H17: =PROPER(TRIM(raw_orders!H17)) -> Punjab | I17: =PROPER(TRIM(raw_orders!I17)) -> Ludhiana | J17: =PROPER(TRIM(raw_orders!J17)) -> Office Supplies | K17: =PROPER(TRIM(raw_orders!K17)) -> Storage | L17: Classic Storage 198 | M17: =PROPER(TRIM(raw_orders!M17)) -> Second Class | N17: 6 | O17: 3965.76 | P17: 0 | Q17: 23794.56 | R17: 15698.47 | S17: 8096.09 | T17: =PROPER(TRIM(raw_orders!T17)) -> Paid | U17: =PROPER(TRIM(raw_orders!U17)) -> Completed | V17: =C17-B17 -> 0 | W17: =IF(AND(P17="",Q17<>"",N17<>"",S17<>""),0,IF(OR(P17<0,P17>1),P17,P17)) -> 0 | X17: =N17*O17*(1-P17) -> 23794.56 | Y17: =X17-R17 -> 8096.09 | Z17: =Y17/X17 -> 0.34024962 | AA17: =TEXT(B17,"MMMM") -> July | AB17: =YEAR(B17) -> 2024 | AC17: =IF(OR(AF17 = "Invalid Discount",AG17="Invalid Discount",AH17="Invalid Shipping Record",AE17="Review Required"),"Invalid",IF(OR(G17="Unknown",M17="Unknown",ISBLANK(P17)),"Warning","Clean")) -> Clean | AD17: =A17&B17&C17&D17&E17&F17&G17&H17&I17&J17&K17&L17&M17&N17&O17&P17&Q17&R17&S17&T17&U17&V17 -> ORD-2024-100164548245482CUST-7656Karan MalhotraSmall BusinessNorthPunjabLudhianaOffice SuppliesStorageClassic Storage 198Second Class63965.76023794.5615698.478096.09PaidCompleted0 | AE17: =IF(COUNTIF($A$2:$A$933,A17)=1,"OK",IF(COUNTIF($AD$2:$AD$933,AD17)>1,"Exact Duplicate", "Review Required")) -> OK | AF17: =IF(P17<0,"Invalid Discount","") | AG17: =IF(P17>1,"Invalid Discount","") | AH17: =IF(V17<0,"Invalid Shipping Record","") | AI17: =IF(ROUND(Q17,2)=ROUND(X17,2),"Match","Mismatch") -> Match | AJ17: =IF(ROUND(S17,2)=ROUND(Y17,2),"Match","Mismatch") -> Match | AK17: =PROPER(TRIM(raw_orders!G17)) -> North | AL17: =PROPER(TRIM(raw_orders!M17)) -> Second Class
A18: ORD-2024-10017 | B18: 45420 | C18: 45427 | D18: CUST-6214 | E18: =PROPER(TRIM(raw_orders!E18)) -> Aarav Sharma | F18: =PROPER(TRIM(raw_orders!F18)) -> Consumer | G18: =PROPER(TRIM(raw_orders!G18)) -> South | H18: =PROPER(TRIM(raw_orders!H18)) -> Telangana | I18: =PROPER(TRIM(raw_orders!I18)) -> Hyderabad | J18: =PROPER(TRIM(raw_orders!J18)) -> Office Supplies | K18: =PROPER(TRIM(raw_orders!K18)) -> Art | L18: Basic Art 204 | M18: =PROPER(TRIM(raw_orders!M18)) -> First Class | N18: 4 | O18: 3323.51 | P18: 0.25 | Q18: 9970.53 | R18: 5668.17 | S18: 4302.36 | T18: =PROPER(TRIM(raw_orders!T18)) -> Paid | U18: =PROPER(TRIM(raw_orders!U18)) -> Completed | V18: =C18-B18 -> 7 | W18: =IF(AND(P18="",Q18<>"",N18<>"",S18<>""),0,IF(OR(P18<0,P18>1),P18,P18)) -> 0.25 | X18: =N18*O18*(1-P18) -> 9970.53 | Y18: =X18-R18 -> 4302.36 | Z18: =Y18/X18 -> 0.43150765 | AA18: =TEXT(B18,"MMMM") -> May | AB18: =YEAR(B18) -> 2024 | AC18: =IF(OR(AF18 = "Invalid Discount",AG18="Invalid Discount",AH18="Invalid Shipping Record",AE18="Review Required"),"Invalid",IF(OR(G18="Unknown",M18="Unknown",ISBLANK(P18)),"Warning","Clean")) -> Clean | AD18: =A18&B18&C18&D18&E18&F18&G18&H18&I18&J18&K18&L18&M18&N18&O18&P18&Q18&R18&S18&T18&U18&V18 -> ORD-2024-100174542045427CUST-6214Aarav SharmaConsumerSouthTelanganaHyderabadOffice SuppliesArtBasic Art 204First Class43323.510.259970.535668.174302.36PaidCompleted7 | AE18: =IF(COUNTIF($A$2:$A$933,A18)=1,"OK",IF(COUNTIF($AD$2:$AD$933,AD18)>1,"Exact Duplicate", "Review Required")) -> OK | AF18: =IF(P18<0,"Invalid Discount","") | AG18: =IF(P18>1,"Invalid Discount","") | AH18: =IF(V18<1,"Invalid Shipping Record","") | AI18: =IF(ROUND(Q18,2)=ROUND(X18,2),"Match","Mismatch") -> Match | AJ18: =IF(ROUND(S18,2)=ROUND(Y18,2),"Match","Mismatch") -> Match | AK18: =PROPER(TRIM(raw_orders!G18)) -> South | AL18: =PROPER(TRIM(raw_orders!M18)) -> First Class
A19: ORD-2024-10018 | B19: 45298 | C19: 45299 | D19: CUST-1626 | E19: =PROPER(TRIM(raw_orders!E19)) -> Sneha Kapoor | F19: =PROPER(TRIM(raw_orders!F19)) -> Small Business | G19: =PROPER(TRIM(raw_orders!G19)) -> North | H19: =PROPER(TRIM(raw_orders!H19)) -> Rajasthan | I19: =PROPER(TRIM(raw_orders!I19)) -> Jaipur | J19: =PROPER(TRIM(raw_orders!J19)) -> Furniture | K19: =PROPER(TRIM(raw_orders!K19)) -> Furnishings | L19: Basic Furnishings 434 | M19: =PROPER(TRIM(raw_orders!M19)) -> Same Day | N19: 5 | O19: 1526.78 | P19: 0 | Q19: 7633.9 | R19: 4706.91 | S19: 2926.99 | T19: =PROPER(TRIM(raw_orders!T19)) -> Paid | U19: =PROPER(TRIM(raw_orders!U19)) -> Completed | V19: =C19-B19 -> 1 | W19: =IF(AND(P19="",Q19<>"",N19<>"",S19<>""),0,IF(OR(P19<0,P19>1),P19,P19)) -> 0 | X19: =N19*O19*(1-P19) -> 7633.9 | Y19: =X19-R19 -> 2926.99 | Z19: =Y19/X19 -> 0.38342001 | AA19: =TEXT(B19,"MMMM") -> January | AB19: =YEAR(B19) -> 2024 | AC19: =IF(OR(AF19 = "Invalid Discount",AG19="Invalid Discount",AH19="Invalid Shipping Record",AE19="Review Required"),"Invalid",IF(OR(G19="Unknown",M19="Unknown",ISBLANK(P19)),"Warning","Clean")) -> Clean | AD19: =A19&B19&C19&D19&E19&F19&G19&H19&I19&J19&K19&L19&M19&N19&O19&P19&Q19&R19&S19&T19&U19&V19 -> ORD-2024-100184529845299CUST-1626Sneha KapoorSmall BusinessNorthRajasthanJaipurFurnitureFurnishingsBasic Furnishings 434Same Day51526.7807633.94706.912926.99PaidCompleted1 | AE19: =IF(COUNTIF($A$2:$A$933,A19)=1,"OK",IF(COUNTIF($AD$2:$AD$933,AD19)>1,"Exact Duplicate", "Review Required")) -> OK | AF19: =IF(P19<0,"Invalid Discount","") | AG19: =IF(P19>1,"Invalid Discount","") | AH19: =IF(V19<1,"Invalid Shipping Record","") | AI19: =IF(ROUND(Q19,2)=ROUND(X19,2),"Match","Mismatch") -> Match | AJ19: =IF(ROUND(S19,2)=ROUND(Y19,2),"Match","Mismatch") -> Match | AK19: =PROPER(TRIM(raw_orders!G19)) -> North | AL19: =PROPER(TRIM(raw_orders!M19)) -> Same Day | AN19: Clean | AO19: =COUNTIF(AC:AC,"Clean") -> 732
A20: ORD-2025-10019 | B20: 45853 | C20: 45855 | D20: CUST-2110 | E20: =PROPER(TRIM(raw_orders!E20)) -> Aarav Sharma | F20: =PROPER(TRIM(raw_orders!F20)) -> Home Office | G20: =PROPER(TRIM(raw_orders!G20)) -> North | H20: =PROPER(TRIM(raw_orders!H20)) -> Uttar Pradesh | I20: =PROPER(TRIM(raw_orders!I20)) -> Noida | J20: =PROPER(TRIM(raw_orders!J20)) -> Technology | K20: =PROPER(TRIM(raw_orders!K20)) -> Copiers | L20: Eco Copiers 755 | M20: =PROPER(TRIM(raw_orders!M20)) -> First Class | N20: 2 | O20: 1997.99 | P20: 0 | Q20: 3995.98 | R20: 2633.2 | S20: 1362.78 | T20: =PROPER(TRIM(raw_orders!T20)) -> Refunded | U20: =PROPER(TRIM(raw_orders!U20)) -> Cancelled | V20: =C20-B20 -> 2 | W20: =IF(AND(P20="",Q20<>"",N20<>"",S20<>""),0,IF(OR(P20<0,P20>1),P20,P20)) -> 0 | X20: =N20*O20*(1-P20) -> 3995.98 | Y20: =X20-R20 -> 1362.78 | Z20: =Y20/X20 -> 0.34103774 | AA20: =TEXT(B20,"MMMM") -> July | AB20: =YEAR(B20) -> 2025 | AC20: =IF(OR(AF20 = "Invalid Discount",AG20="Invalid Discount",AH20="Invalid Shipping Record",AE20="Review Required"),"Invalid",IF(OR(G20="Unknown",M20="Unknown",ISBLANK(P20)),"Warning","Clean")) -> Clean | AD20: =A20&B20&C20&D20&E20&F20&G20&H20&I20&J20&K20&L20&M20&N20&O20&P20&Q20&R20&S20&T20&U20&V20 -> ORD-2025-100194585345855CUST-2110Aarav SharmaHome OfficeNorthUttar PradeshNoidaTechnologyCopiersEco Copiers 755First Class21997.9903995.982633.21362.78RefundedCancelled2 | AE20: =IF(COUNTIF($A$2:$A$933,A20)=1,"OK",IF(COUNTIF($AD$2:$AD$933,AD20)>1,"Exact Duplicate", "Review Required")) -> OK | AF20: =IF(P20<0,"Invalid Discount","") | AG20: =IF(P20>1,"Invalid Discount","") | AH20: =IF(V20<1,"Invalid Shipping Record","") | AI20: =IF(ROUND(Q20,2)=ROUND(X20,2),"Match","Mismatch") -> Match | AJ20: =IF(ROUND(S20,2)=ROUND(Y20,2),"Match","Mismatch") -> Match | AK20: =PROPER(TRIM(raw_orders!G20)) -> North | AL20: =PROPER(TRIM(raw_orders!M20)) -> First Class | AN20: Warning | AO20: =COUNTIF(AC:AC,"Warning") -> 52
A21: ORD-2024-10020 | B21: 45500 | C21: 45504 | D21: CUST-3186 | E21: =PROPER(TRIM(raw_orders!E21)) -> Rohan Mehta | F21: =PROPER(TRIM(raw_orders!F21)) -> Home Office | G21: =PROPER(TRIM(raw_orders!G21)) -> West | H21: =PROPER(TRIM(raw_orders!H21)) -> Madhya Pradesh | I21: =PROPER(TRIM(raw_orders!I21)) -> Indore | J21: =PROPER(TRIM(raw_orders!J21)) -> Office Supplies | K21: =PROPER(TRIM(raw_orders!K21)) -> Storage | L21: Prime Storage 121 | M21: =PROPER(TRIM(raw_orders!M21)) -> Second Class | N21: 3 | O21: 3887.94 | P21: -0.19 | Q21: 9331.06 | R21: 7529.31 | S21: 1801.75 | T21: =PROPER(TRIM(raw_orders!T21)) -> Paid | U21: =PROPER(TRIM(raw_orders!U21)) -> Completed | V21: =C21-B21 -> 4 | W21: =IF(AND(P21="",Q21<>"",N21<>"",S21<>""),0,IF(OR(P21<0,P21>1),P21,P21)) -> -0.19 | X21: =N21*O21*(1-P21) -> 13879.946 | Y21: =X21-R21 -> 6350.6358 | Z21: =Y21/X21 -> 0.45754039 | AA21: =TEXT(B21,"MMMM") -> July | AB21: =YEAR(B21) -> 2024 | AC21: =IF(OR(AF21 = "Invalid Discount",AG21="Invalid Discount",AH21="Invalid Shipping Record",AE21="Review Required"),"Invalid",IF(OR(G21="Unknown",M21="Unknown",ISBLANK(P21)),"Warning","Clean")) -> Invalid | AD21: =A21&B21&C21&D21&E21&F21&G21&H21&I21&J21&K21&L21&M21&N21&O21&P21&Q21&R21&S21&T21&U21&V21 -> ORD-2024-100204550045504CUST-3186Rohan MehtaHome OfficeWestMadhya PradeshIndoreOffice SuppliesStoragePrime Storage 121Second Class33887.94-0.199331.067529.311801.75PaidCompleted4 | AE21: =IF(COUNTIF($A$2:$A$933,A21)=1,"OK",IF(COUNTIF($AD$2:$AD$933,AD21)>1,"Exact Duplicate", "Review Required")) -> OK | AF21: =IF(P21<0,"Invalid Discount","") -> Invalid Discount | AG21: =IF(P21>1,"Invalid Discount","") | AH21: =IF(V21<1,"Invalid Shipping Record","") | AI21: =IF(ROUND(Q21,2)=ROUND(X21,2),"Match","Mismatch") -> Mismatch | AJ21: =IF(ROUND(S21,2)=ROUND(Y21,2),"Match","Mismatch") -> Mismatch | AK21: =PROPER(TRIM(raw_orders!G21)) -> West | AL21: =PROPER(TRIM(raw_orders!M21)) -> Second Class | AN21: Invalid | AO21: =COUNTIF(AC:AC,"Invalid") -> 128
A22: ORD-2025-10021 | B22: 45678 | C22: 45680 | D22: CUST-3190 | E22: =PROPER(TRIM(raw_orders!E22)) -> Aditi Sen | F22: =PROPER(TRIM(raw_orders!F22)) -> Home Office | G22: =PROPER(TRIM(raw_orders!G22)) -> East | H22: =PROPER(TRIM(raw_orders!H22)) -> Bihar | I22: =PROPER(TRIM(raw_orders!I22)) -> Patna | J22: =PROPER(TRIM(raw_orders!J22)) -> Technology | K22: =PROPER(TRIM(raw_orders!K22)) -> Copiers | L22: Elite Copiers 233 | M22: =PROPER(TRIM(raw_orders!M22)) -> First Class | N22: 5 | O22: 4373.06 | P22: 0.25 | Q22: 16398.98 | R22: 9556.52 | S22: 6842.46 | T22: =PROPER(TRIM(raw_orders!T22)) -> Paid | U22: =PROPER(TRIM(raw_orders!U22)) -> Completed | V22: =C22-B22 -> 2 | W22: =IF(AND(P22="",Q22<>"",N22<>"",S22<>""),0,IF(OR(P22<0,P22>1),P22,P22)) -> 0.25 | X22: =N22*O22*(1-P22) -> 16398.975 | Y22: =X22-R22 -> 6842.455 | Z22: =Y22/X22 -> 0.41724894 | AA22: =TEXT(B22,"MMMM") -> January | AB22: =YEAR(B22) -> 2025 | AC22: =IF(OR(AF22 = "Invalid Discount",AG22="Invalid Discount",AH22="Invalid Shipping Record",AE22="Review Required"),"Invalid",IF(OR(G22="Unknown",M22="Unknown",ISBLANK(P22)),"Warning","Clean")) -> Clean | AD22: =A22&B22&C22&D22&E22&F22&G22&H22&I22&J22&K22&L22&M22&N22&O22&P22&Q22&R22&S22&T22&U22&V22 -> ORD-2025-100214567845680CUST-3190Aditi SenHome OfficeEastBiharPatnaTechnologyCopiersElite Copiers 233First Class54373.060.2516398.989556.526842.46PaidCompleted2 | AE22: =IF(COUNTIF($A$2:$A$933,A22)=1,"OK",IF(COUNTIF($AD$2:$AD$933,AD22)>1,"Exact Duplicate", "Review Required")) -> OK | AF22: =IF(P22<0,"Invalid Discount","") | AG22: =IF(P22>1,"Invalid Discount","") | AH22: =IF(V22<1,"Invalid Shipping Record","") | AI22: =IF(ROUND(Q22,2)=ROUND(X22,2),"Match","Mismatch") -> Match | AJ22: =IF(ROUND(S22,2)=ROUND(Y22,2),"Match","Mismatch") -> Match | AK22: =PROPER(TRIM(raw_orders!G22)) -> East | AL22: =PROPER(TRIM(raw_orders!M22)) -> First Class
A23: ORD-2025-10022 | B23: 45681 | C23: 45687 | D23: CUST-3036 | E23: =PROPER(TRIM(raw_orders!E23)) -> Sneha Kapoor | F23: =PROPER(TRIM(raw_orders!F23)) -> Consumer | G23: =PROPER(TRIM(raw_orders!G23)) -> West | H23: =PROPER(TRIM(raw_orders!H23)) -> Madhya Pradesh | I23: =PROPER(TRIM(raw_orders!I23)) -> Indore | J23: =PROPER(TRIM(raw_orders!J23)) -> Furniture | K23: =PROPER(TRIM(raw_orders!K23)) -> Furnishings | L23: Eco Furnishings 897 | M23: =PROPER(TRIM(raw_orders!M23)) -> Second Class | N23: 4 | O23: 697.69 | P23: -0.23 | Q23: 2790.76 | R23: 2037.71 | S23: 753.05 | T23: =PROPER(TRIM(raw_orders!T23)) -> Paid | U23: =PROPER(TRIM(raw_orders!U23)) -> Completed | V23: =C23-B23 -> 6 | W23: =IF(AND(P23="",Q23<>"",N23<>"",S23<>""),0,IF(OR(P23<0,P23>1),P23,P23)) -> -0.23 | X23: =N23*O23*(1-P23) -> 3432.6348 | Y23: =X23-R23 -> 1394.9248 | Z23: =Y23/X23 -> 0.40637146 | AA23: =TEXT(B23,"MMMM") -> January | AB23: =YEAR(B23) -> 2025 | AC23: =IF(OR(AF23 = "Invalid Discount",AG23="Invalid Discount",AH23="Invalid Shipping Record",AE23="Review Required"),"Invalid",IF(OR(G23="Unknown",M23="Unknown",ISBLANK(P23)),"Warning","Clean")) -> Invalid | AD23: =A23&B23&C23&D23&E23&F23&G23&H23&I23&J23&K23&L23&M23&N23&O23&P23&Q23&R23&S23&T23&U23&V23 -> ORD-2025-100224568145687CUST-3036Sneha KapoorConsumerWestMadhya PradeshIndoreFurnitureFurnishingsEco Furnishings 897Second Class4697.69-0.232790.762037.71753.05PaidCompleted6 | AE23: =IF(COUNTIF($A$2:$A$933,A23)=1,"OK",IF(COUNTIF($AD$2:$AD$933,AD23)>1,"Exact Duplicate", "Review Required")) -> OK | AF23: =IF(P23<0,"Invalid Discount","") -> Invalid Discount | AG23: =IF(P23>1,"Invalid Discount","") | AH23: =IF(V23<1,"Invalid Shipping Record","") | AI23: =IF(ROUND(Q23,2)=ROUND(X23,2),"Match","Mismatch") -> Mismatch | AJ23: =IF(ROUND(S23,2)=ROUND(Y23,2),"Match","Mismatch") -> Mismatch | AK23: =PROPER(TRIM(raw_orders!G23)) -> West | AL23: =PROPER(TRIM(raw_orders!M23)) -> Second Class | AN23: Duplicate Check
A24: ORD-2025-10023 | B24: 45676 | C24: 45678 | D24: CUST-3588 | E24: =PROPER(TRIM(raw_orders!E24)) -> Mira Das | F24: =PROPER(TRIM(raw_orders!F24)) -> Consumer | G24: =PROPER(TRIM(raw_orders!G24)) -> South | H24: =PROPER(TRIM(raw_orders!H24)) -> Telangana | I24: =PROPER(TRIM(raw_orders!I24)) -> Hyderabad | J24: =PROPER(TRIM(raw_orders!J24)) -> Office Supplies | K24: =PROPER(TRIM(raw_orders!K24)) -> Binders | L24: Max Binders 355 | M24: =PROPER(TRIM(raw_orders!M24)) -> Standard Class | N24: 8 | O24: 1219.34 | P24: 0.15 | Q24: 8291.51 | R24: 6685.03 | S24: 1606.48 | T24: =PROPER(TRIM(raw_orders!T24)) -> Failed | U24: =PROPER(TRIM(raw_orders!U24)) -> Returned | V24: =C24-B24 -> 2 | W24: =IF(AND(P24="",Q24<>"",N24<>"",S24<>""),0,IF(OR(P24<0,P24>1),P24,P24)) -> 0.15 | X24: =N24*O24*(1-P24) -> 8291.512 | Y24: =X24-R24 -> 1606.482 | Z24: =Y24/X24 -> 0.19375019 | AA24: =TEXT(B24,"MMMM") -> January | AB24: =YEAR(B24) -> 2025 | AC24: =IF(OR(AF24 = "Invalid Discount",AG24="Invalid Discount",AH24="Invalid Shipping Record",AE24="Review Required"),"Invalid",IF(OR(G24="Unknown",M24="Unknown",ISBLANK(P24)),"Warning","Clean")) -> Clean | AD24: =A24&B24&C24&D24&E24&F24&G24&H24&I24&J24&K24&L24&M24&N24&O24&P24&Q24&R24&S24&T24&U24&V24 -> ORD-2025-100234567645678CUST-3588Mira DasConsumerSouthTelanganaHyderabadOffice SuppliesBindersMax Binders 355Standard Class81219.340.158291.516685.031606.48FailedReturned2 | AE24: =IF(COUNTIF($A$2:$A$933,A24)=1,"OK",IF(COUNTIF($AD$2:$AD$933,AD24)>1,"Exact Duplicate", "Review Required")) -> OK | AF24: =IF(P24<0,"Invalid Discount","") | AG24: =IF(P24>1,"Invalid Discount","") | AH24: =IF(V24<1,"Invalid Shipping Record","") | AI24: =IF(ROUND(Q24,2)=ROUND(X24,2),"Match","Mismatch") -> Match | AJ24: =IF(ROUND(S24,2)=ROUND(Y24,2),"Match","Mismatch") -> Match | AK24: =PROPER(TRIM(raw_orders!G24)) -> South | AL24: =PROPER(TRIM(raw_orders!M24)) -> Standard Class | AN24: OK | AO24: =COUNTIF(AE:AE,"OK") -> 888
A25: ORD-2025-10024 | B25: 45898 | C25: 45900 | D25: CUST-7098 | E25: =PROPER(TRIM(raw_orders!E25)) -> Rahul Verma | F25: =PROPER(TRIM(raw_orders!F25)) -> Home Office | G25: =PROPER(TRIM(raw_orders!G25)) -> East | H25: =PROPER(TRIM(raw_orders!H25)) -> Bihar | I25: =PROPER(TRIM(raw_orders!I25)) -> Patna | J25: =PROPER(TRIM(raw_orders!J25)) -> Furniture | K25: =PROPER(TRIM(raw_orders!K25)) -> Bookcases | L25: Pro Bookcases 394 | M25: =PROPER(TRIM(raw_orders!M25)) -> First Class | N25: 4 | O25: 1958.01 | P25: 0.2 | Q25: 6265.63 | R25: 4321.86 | S25: 1943.77 | T25: =PROPER(TRIM(raw_orders!T25)) -> Paid | U25: =PROPER(TRIM(raw_orders!U25)) -> Completed | V25: =C25-B25 -> 2 | W25: =IF(AND(P25="",Q25<>"",N25<>"",S25<>""),0,IF(OR(P25<0,P25>1),P25,P25)) -> 0.2 | X25: =N25*O25*(1-P25) -> 6265.632 | Y25: =X25-R25 -> 1943.772 | Z25: =Y25/X25 -> 0.3102276 | AA25: =TEXT(B25,"MMMM") -> August | AB25: =YEAR(B25) -> 2025 | AC25: =IF(OR(AF25 = "Invalid Discount",AG25="Invalid Discount",AH25="Invalid Shipping Record",AE25="Review Required"),"Invalid",IF(OR(G25="Unknown",M25="Unknown",ISBLANK(P25)),"Warning","Clean")) -> Clean | AD25: =A25&B25&C25&D25&E25&F25&G25&H25&I25&J25&K25&L25&M25&N25&O25&P25&Q25&R25&S25&T25&U25&V25 -> ORD-2025-100244589845900CUST-7098Rahul VermaHome OfficeEastBiharPatnaFurnitureBookcasesPro Bookcases 394First Class41958.010.26265.634321.861943.77PaidCompleted2 | AE25: =IF(COUNTIF($A$2:$A$933,A25)=1,"OK",IF(COUNTIF($AD$2:$AD$933,AD25)>1,"Exact Duplicate", "Review Required")) -> OK | AF25: =IF(P25<0,"Invalid Discount","") | AG25: =IF(P25>1,"Invalid Discount","") | AH25: =IF(V25<1,"Invalid Shipping Record","") | AI25: =IF(ROUND(Q25,2)=ROUND(X25,2),"Match","Mismatch") -> Match | AJ25: =IF(ROUND(S25,2)=ROUND(Y25,2),"Match","Mismatch") -> Match | AK25: =PROPER(TRIM(raw_orders!G25)) -> East | AL25: =PROPER(TRIM(raw_orders!M25)) -> First Class | AN25: Review Required | AO25: =COUNTIF(AE:AE,"Review Required") -> 24
A26: ORD-2024-10025 | B26: 45355 | C26: 45352 | D26: CUST-1747 | E26: =PROPER(TRIM(raw_orders!E26)) -> Diya Patel | F26: =PROPER(TRIM(raw_orders!F26)) -> Consumer | G26: =PROPER(TRIM(raw_orders!G26)) -> North | H26: =PROPER(TRIM(raw_orders!H26)) -> Punjab | I26: =PROPER(TRIM(raw_orders!I26)) -> Ludhiana | J26: =PROPER(TRIM(raw_orders!J26)) -> Office Supplies | K26: =PROPER(TRIM(raw_orders!K26)) -> Art | L26: Max Art 215 | M26: =PROPER(TRIM(raw_orders!M26)) -> Standard Class | N26: 4 | O26: 4492.94 | P26: 0.25 | Q26: 13478.82 | R26: 10937.35 | S26: 2541.47 | T26: =PROPER(TRIM(raw_orders!T26)) -> Pending | U26: =PROPER(TRIM(raw_orders!U26)) -> Cancelled | V26: =C26-B26 -> -3 | W26: =IF(AND(P26="",Q26<>"",N26<>"",S26<>""),0,IF(OR(P26<0,P26>1),P26,P26)) -> 0.25 | X26: =N26*O26*(1-P26) -> 13478.82 | Y26: =X26-R26 -> 2541.47 | Z26: =Y26/X26 -> 0.18855286 | AA26: =TEXT(B26,"MMMM") -> March | AB26: =YEAR(B26) -> 2024 | AC26: =IF(OR(AF26 = "Invalid Discount",AG26="Invalid Discount",AH26="Invalid Shipping Record",AE26="Review Required"),"Invalid",IF(OR(G26="Unknown",M26="Unknown",ISBLANK(P26)),"Warning","Clean")) -> Invalid | AD26: =A26&B26&C26&D26&E26&F26&G26&H26&I26&J26&K26&L26&M26&N26&O26&P26&Q26&R26&S26&T26&U26&V26 -> ORD-2024-100254535545352CUST-1747Diya PatelConsumerNorthPunjabLudhianaOffice SuppliesArtMax Art 215Standard Class44492.940.2513478.8210937.352541.47PendingCancelled-3 | AE26: =IF(COUNTIF($A$2:$A$933,A26)=1,"OK",IF(COUNTIF($AD$2:$AD$933,AD26)>1,"Exact Duplicate", "Review Required")) -> OK | AF26: =IF(P26<0,"Invalid Discount","") | AG26: =IF(P26>1,"Invalid Discount","") | AH26: =IF(V26<0,"Invalid Shipping Record","") -> Invalid Shipping Record | AI26: =IF(ROUND(Q26,2)=ROUND(X26,2),"Match","Mismatch") -> Match | AJ26: =IF(ROUND(S26,2)=ROUND(Y26,2),"Match","Mismatch") -> Match | AK26: =PROPER(TRIM(raw_orders!G26)) -> North | AL26: =PROPER(TRIM(raw_orders!M26)) -> Standard Class
A27: ORD-2024-10026 | B27: 45606 | C27: 45584 | D27: CUST-1731 | E27: =PROPER(TRIM(raw_orders!E27)) -> Arjun Bose | F27: =PROPER(TRIM(raw_orders!F27)) -> Corporate | G27: =PROPER(TRIM(raw_orders!G27)) -> East | H27: =PROPER(TRIM(raw_orders!H27)) -> Assam | I27: =PROPER(TRIM(raw_orders!I27)) -> Guwahati | J27: =PROPER(TRIM(raw_orders!J27)) -> Technology | K27: =PROPER(TRIM(raw_orders!K27)) -> Accessories | L27: Classic Accessories 478 | M27: =PROPER(TRIM(raw_orders!M27)) -> First Class | N27: 2 | O27: 4315.2 | P27: 0.15 | Q27: 7335.84 | R27: 4968.41 | S27: 2367.43 | T27: =PROPER(TRIM(raw_orders!T27)) -> Paid | U27: =PROPER(TRIM(raw_orders!U27)) -> Completed | V27: =C27-B27 -> -22 | W27: =IF(AND(P27="",Q27<>"",N27<>"",S27<>""),0,IF(OR(P27<0,P27>1),P27,P27)) -> 0.15 | X27: =N27*O27*(1-P27) -> 7335.84 | Y27: =X27-R27 -> 2367.43 | Z27: =Y27/X27 -> 0.32272105 | AA27: =TEXT(B27,"MMMM") -> November | AB27: =YEAR(B27) -> 2024 | AC27: =IF(OR(AF27 = "Invalid Discount",AG27="Invalid Discount",AH27="Invalid Shipping Record",AE27="Review Required"),"Invalid",IF(OR(G27="Unknown",M27="Unknown",ISBLANK(P27)),"Warning","Clean")) -> Invalid | AD27: =A27&B27&C27&D27&E27&F27&G27&H27&I27&J27&K27&L27&M27&N27&O27&P27&Q27&R27&S27&T27&U27&V27 -> ORD-2024-100264560645584CUST-1731Arjun BoseCorporateEastAssamGuwahatiTechnologyAccessoriesClassic Accessories 478First Class24315.20.157335.844968.412367.43PaidCompleted-22 | AE27: =IF(COUNTIF($A$2:$A$933,A27)=1,"OK",IF(COUNTIF($AD$2:$AD$933,AD27)>1,"Exact Duplicate", "Review Required")) -> OK | AF27: =IF(P27<0,"Invalid Discount","") | AG27: =IF(P27>1,"Invalid Discount","") | AH27: =IF(V27<0,"Invalid Shipping Record","") -> Invalid Shipping Record | AI27: =IF(ROUND(Q27,2)=ROUND(X27,2),"Match","Mismatch") -> Match | AJ27: =IF(ROUND(S27,2)=ROUND(Y27,2),"Match","Mismatch") -> Match | AK27: =PROPER(TRIM(raw_orders!G27)) -> East | AL27: =PROPER(TRIM(raw_orders!M27)) -> First Class | AN27: Total Records | AO27: =COUNTA(A2:A913) -> 912
A28: ORD-2024-10027 | B28: 45619 | C28: 45619 | D28: CUST-4401 | E28: =PROPER(TRIM(raw_orders!E28)) -> Diya Patel | F28: =PROPER(TRIM(raw_orders!F28)) -> Corporate | G28: =PROPER(TRIM(raw_orders!G28)) -> North | H28: =PROPER(TRIM(raw_orders!H28)) -> Uttar Pradesh | I28: =PROPER(TRIM(raw_orders!I28)) -> Noida | J28: =PROPER(TRIM(raw_orders!J28)) -> Technology | K28: =PROPER(TRIM(raw_orders!K28)) -> Phones | L28: Pro Phones 243 | M28: =PROPER(TRIM(raw_orders!M28)) -> Standard Class | N28: 4 | O28: 716.13 | P28: 0.1 | Q28: 2578.07 | R28: 1527.55 | S28: 1050.52 | T28: =PROPER(TRIM(raw_orders!T28)) -> Paid | U28: =PROPER(TRIM(raw_orders!U28)) -> Returned | V28: =C28-B28 -> 0 | W28: =IF(AND(P28="",Q28<>"",N28<>"",S28<>""),0,IF(OR(P28<0,P28>1),P28,P28)) -> 0.1 | X28: =N28*O28*(1-P28) -> 2578.068 | Y28: =X28-R28 -> 1050.518 | Z28: =Y28/X28 -> 0.40748266 | AA28: =TEXT(B28,"MMMM") -> November | AB28: =YEAR(B28) -> 2024 | AC28: =IF(OR(AF28 = "Invalid Discount",AG28="Invalid Discount",AH28="Invalid Shipping Record",AE28="Review Required"),"Invalid",IF(OR(G28="Unknown",M28="Unknown",ISBLANK(P28)),"Warning","Clean")) -> Clean | AD28: =A28&B28&C28&D28&E28&F28&G28&H28&I28&J28&K28&L28&M28&N28&O28&P28&Q28&R28&S28&T28&U28&V28 -> ORD-2024-100274561945619CUST-4401Diya PatelCorporateNorthUttar PradeshNoidaTechnologyPhonesPro Phones 243Standard Class4716.130.12578.071527.551050.52PaidReturned0 | AE28: =IF(COUNTIF($A$2:$A$933,A28)=1,"OK",IF(COUNTIF($AD$2:$AD$933,AD28)>1,"Exact Duplicate", "Review Required")) -> OK | AF28: =IF(P28<0,"Invalid Discount","") | AG28: =IF(P28>1,"Invalid Discount","") | AH28: =IF(V28<0,"Invalid Shipping Record","") | AI28: =IF(ROUND(Q28,2)=ROUND(X28,2),"Match","Mismatch") -> Match | AJ28: =IF(ROUND(S28,2)=ROUND(Y28,2),"Match","Mismatch") -> Match | AK28: =PROPER(TRIM(raw_orders!G28)) -> North | AL28: =PROPER(TRIM(raw_orders!M28)) -> Standard Class
A29: ORD-2025-10028 | B29: 45929 | C29: 45787 | D29: CUST-9875 | E29: =PROPER(TRIM(raw_orders!E29)) -> Arjun Bose | F29: =PROPER(TRIM(raw_orders!F29)) -> Small Business | G29: =PROPER(TRIM(raw_orders!G29)) -> South | H29: =PROPER(TRIM(raw_orders!H29)) -> Karnataka | I29: =PROPER(TRIM(raw_orders!I29)) -> Bengaluru | J29: =PROPER(TRIM(raw_orders!J29)) -> Office Supplies | K29: =PROPER(TRIM(raw_orders!K29)) -> Paper | L29: Basic Paper 613 | M29: =PROPER(TRIM(raw_orders!M29)) -> Second Class | N29: 5 | O29: 1806.51 | P29: 0.25 | Q29: 6774.41 | R29: 4710.36 | S29: 2064.05 | T29: =PROPER(TRIM(raw_orders!T29)) -> Failed | U29: =PROPER(TRIM(raw_orders!U29)) -> Returned | V29: =C29-B29 -> -142 | W29: =IF(AND(P29="",Q29<>"",N29<>"",S29<>""),0,IF(OR(P29<0,P29>1),P29,P29)) -> 0.25 | X29: =N29*O29*(1-P29) -> 6774.4125 | Y29: =X29-R29 -> 2064.0525 | Z29: =Y29/X29 -> 0.30468362 | AA29: =TEXT(B29,"MMMM") -> September | AB29: =YEAR(B29) -> 2025 | AC29: =IF(OR(AF29 = "Invalid Discount",AG29="Invalid Discount",AH29="Invalid Shipping Record",AE29="Review Required"),"Invalid",IF(OR(G29="Unknown",M29="Unknown",ISBLANK(P29)),"Warning","Clean")) -> Invalid | AD29: =A29&B29&C29&D29&E29&F29&G29&H29&I29&J29&K29&L29&M29&N29&O29&P29&Q29&R29&S29&T29&U29&V29 -> ORD-2025-100284592945787CUST-9875Arjun BoseSmall BusinessSouthKarnatakaBengaluruOffice SuppliesPaperBasic Paper 613Second Class51806.510.256774.414710.362064.05FailedReturned-142 | AE29: =IF(COUNTIF($A$2:$A$933,A29)=1,"OK",IF(COUNTIF($AD$2:$AD$933,AD29)>1,"Exact Duplicate", "Review Required")) -> OK | AF29: =IF(P29<0,"Invalid Discount","") | AG29: =IF(P29>1,"Invalid Discount","") | AH29: =IF(V29<0,"Invalid Shipping Record","") -> Invalid Shipping Record | AI29: =IF(ROUND(Q29,2)=ROUND(X29,2),"Match","Mismatch") -> Match | AJ29: =IF(ROUND(S29,2)=ROUND(Y29,2),"Match","Mismatch") -> Match | AK29: =PROPER(TRIM(raw_orders!G29)) -> South | AL29: =PROPER(TRIM(raw_orders!M29)) -> Second Class | AN29: Number of Sales mismatched Records | AO29: =COUNTIF(AI:AI,"Mismatch") -> 93
A30: ORD-2024-10029 | B30: 45606 | C30: 45583 | D30: CUST-1569 | E30: =PROPER(TRIM(raw_orders!E30)) -> Ananya Rao | F30: =PROPER(TRIM(raw_orders!F30)) -> Home Office | G30: =PROPER(TRIM(raw_orders!G30)) -> West | H30: =PROPER(TRIM(raw_orders!H30)) -> Gujarat | I30: =PROPER(TRIM(raw_orders!I30)) -> Ahmedabad | J30: =PROPER(TRIM(raw_orders!J30)) -> Technology | K30: =PROPER(TRIM(raw_orders!K30)) -> Phones | L30: Prime Phones 698 | M30: =PROPER(TRIM(raw_orders!M30)) -> Second Class | N30: 2 | O30: 1942.22 | P30: 0.25 | Q30: 2913.33 | R30: 2122.33 | S30: 791 | T30: =PROPER(TRIM(raw_orders!T30)) -> Refunded | U30: =PROPER(TRIM(raw_orders!U30)) -> Cancelled | V30: =C30-B30 -> -23 | W30: =IF(AND(P30="",Q30<>"",N30<>"",S30<>""),0,IF(OR(P30<0,P30>1),P30,P30)) -> 0.25 | X30: =N30*O30*(1-P30) -> 2913.33 | Y30: =X30-R30 -> 791 | Z30: =Y30/X30 -> 0.27151061 | AA30: =TEXT(B30,"MMMM") -> November | AB30: =YEAR(B30) -> 2024 | AC30: =IF(OR(AF30 = "Invalid Discount",AG30="Invalid Discount",AH30="Invalid Shipping Record",AE30="Review Required"),"Invalid",IF(OR(G30="Unknown",M30="Unknown",ISBLANK(P30)),"Warning","Clean")) -> Invalid | AD30: =A30&B30&C30&D30&E30&F30&G30&H30&I30&J30&K30&L30&M30&N30&O30&P30&Q30&R30&S30&T30&U30&V30 -> ORD-2024-100294560645583CUST-1569Ananya RaoHome OfficeWestGujaratAhmedabadTechnologyPhonesPrime Phones 698Second Class21942.220.252913.332122.33791RefundedCancelled-23 | AE30: =IF(COUNTIF($A$2:$A$933,A30)=1,"OK",IF(COUNTIF($AD$2:$AD$933,AD30)>1,"Exact Duplicate", "Review Required")) -> OK | AF30: =IF(P30<0,"Invalid Discount","") | AG30: =IF(P30>1,"Invalid Discount","") | AH30: =IF(V30<0,"Invalid Shipping Record","") -> Invalid Shipping Record | AI30: =IF(ROUND(Q30,2)=ROUND(X30,2),"Match","Mismatch") -> Match | AJ30: =IF(ROUND(S30,2)=ROUND(Y30,2),"Match","Mismatch") -> Match | AK30: =PROPER(TRIM(raw_orders!G30)) -> West | AL30: =PROPER(TRIM(raw_orders!M30)) -> Second Class
A31: ORD-2025-10030 | B31: 45882 | C31: 45882 | D31: CUST-5936 | E31: =PROPER(TRIM(raw_orders!E31)) -> Rohan Mehta | F31: =PROPER(TRIM(raw_orders!F31)) -> Home Office | G31: =PROPER(TRIM(raw_orders!G31)) -> South | H31: =PROPER(TRIM(raw_orders!H31)) -> Kerala | I31: =PROPER(TRIM(raw_orders!I31)) -> Kochi | J31: =PROPER(TRIM(raw_orders!J31)) -> Technology | K31: =PROPER(TRIM(raw_orders!K31)) -> Phones | L31: Pro Phones 442 | M31: =PROPER(TRIM(raw_orders!M31)) -> Standard Class | N31: 1 | O31: 256.01 | P31: 0.15 | Q31: 217.61 | R31: 119.77 | S31: 97.84 | T31: =PROPER(TRIM(raw_orders!T31)) -> Paid | U31: =PROPER(TRIM(raw_orders!U31)) -> Completed | V31: =C31-B31 -> 0 | W31: =IF(AND(P31="",Q31<>"",N31<>"",S31<>""),0,IF(OR(P31<0,P31>1),P31,P31)) -> 0.15 | X31: =N31*O31*(1-P31) -> 217.6085 | Y31: =X31-R31 -> 97.8385 | Z31: =Y31/X31 -> 0.4496079 | AA31: =TEXT(B31,"MMMM") -> August | AB31: =YEAR(B31) -> 2025 | AC31: =IF(OR(AF31 = "Invalid Discount",AG31="Invalid Discount",AH31="Invalid Shipping Record",AE31="Review Required"),"Invalid",IF(OR(G31="Unknown",M31="Unknown",ISBLANK(P31)),"Warning","Clean")) -> Clean | AD31: =A31&B31&C31&D31&E31&F31&G31&H31&I31&J31&K31&L31&M31&N31&O31&P31&Q31&R31&S31&T31&U31&V31 -> ORD-2025-100304588245882CUST-5936Rohan MehtaHome OfficeSouthKeralaKochiTechnologyPhonesPro Phones 442Standard Class1256.010.15217.61119.7797.84PaidCompleted0 | AE31: =IF(COUNTIF($A$2:$A$933,A31)=1,"OK",IF(COUNTIF($AD$2:$AD$933,AD31)>1,"Exact Duplicate", "Review Required")) -> OK | AF31: =IF(P31<0,"Invalid Discount","") | AG31: =IF(P31>1,"Invalid Discount","") | AH31: =IF(V31<0,"Invalid Shipping Record","") | AI31: =IF(ROUND(Q31,2)=ROUND(X31,2),"Match","Mismatch") -> Match | AJ31: =IF(ROUND(S31,2)=ROUND(Y31,2),"Match","Mismatch") -> Match | AK31: =PROPER(TRIM(raw_orders!G31)) -> South | AL31: =PROPER(TRIM(raw_orders!M31)) -> Standard Class | AN31: Number of Profit mismatched Records | AO31: =COUNTIF(AJ:AJ,"Mismatch") -> 94
A32: ORD-2024-10031 | B32: 45331 | C32: 45334 | D32: CUST-8759 | E32: =PROPER(TRIM(raw_orders!E32)) -> Ananya Rao | F32: =PROPER(TRIM(raw_orders!F32)) -> Corporate | G32: =PROPER(TRIM(raw_orders!G32)) -> West | H32: =PROPER(TRIM(raw_orders!H32)) -> Goa | I32: =PROPER(TRIM(raw_orders!I32)) -> Panaji | J32: =PROPER(TRIM(raw_orders!J32)) -> Office Supplies | K32: =PROPER(TRIM(raw_orders!K32)) -> Labels | L32: Pro Labels 355 | M32: =PROPER(TRIM(raw_orders!M32)) -> First Class | N32: 1 | O32: 3421.77 | P32: 0.1 | Q32: 3079.59 | R32: 2001.89 | S32: 1077.7 | T32: =PROPER(TRIM(raw_orders!T32)) -> Paid | U32: =PROPER(TRIM(raw_orders!U32)) -> Completed | V32: =C32-B32 -> 3 | W32: =IF(AND(P32="",Q32<>"",N32<>"",S32<>""),0,IF(OR(P32<0,P32>1),P32,P32)) -> 0.1 | X32: =N32*O32*(1-P32) -> 3079.593 | Y32: =X32-R32 -> 1077.703 | Z32: =Y32/X32 -> 0.34994981 | AA32: =TEXT(B32,"MMMM") -> February | AB32: =YEAR(B32) -> 2024 | AC32: =IF(OR(AF32 = "Invalid Discount",AG32="Invalid Discount",AH32="Invalid Shipping Record",AE32="Review Required"),"Invalid",IF(OR(G32="Unknown",M32="Unknown",ISBLANK(P32)),"Warning","Clean")) -> Clean | AD32: =A32&B32&C32&D32&E32&F32&G32&H32&I32&J32&K32&L32&M32&N32&O32&P32&Q32&R32&S32&T32&U32&V32 -> ORD-2024-100314533145334CUST-8759Ananya RaoCorporateWestGoaPanajiOffice SuppliesLabelsPro Labels 355First Class13421.770.13079.592001.891077.7PaidCompleted3 | AE32: =IF(COUNTIF($A$2:$A$933,A32)=1,"OK",IF(COUNTIF($AD$2:$AD$933,AD32)>1,"Exact Duplicate", "Review Required")) -> OK | AF32: =IF(P32<0,"Invalid Discount","") | AG32: =IF(P32>1,"Invalid Discount","") | AH32: =IF(V32<1,"Invalid Shipping Record","") | AI32: =IF(ROUND(Q32,2)=ROUND(X32,2),"Match","Mismatch") -> Match | AJ32: =IF(ROUND(S32,2)=ROUND(Y32,2),"Match","Mismatch") -> Match | AK32: =PROPER(TRIM(raw_orders!G32)) -> West | AL32: =PROPER(TRIM(raw_orders!M32)) -> First Class
